<?xml version="1.0" encoding="UTF-8"?>
<testng-results ignored="0" total="4" passed="2" failed="1" skipped="1">
  <reporter-output>
  </reporter-output>
  <suite started-at="2022-06-28T11:34:04Z" name="Suite" finished-at="2022-06-28T11:34:45Z" duration-ms="40917">
    <groups>
    </groups>
    <test started-at="2022-06-28T11:34:04Z" name="Test" finished-at="2022-06-28T11:34:45Z" duration-ms="40917">
      <class name="Tests.UseInsider">
        <test-method signature="openBrowser()[pri:0, instance:Tests.UseInsider@44e3a2b2]" started-at="2022-06-28T11:34:04Z" name="openBrowser" finished-at="2022-06-28T11:34:24Z" duration-ms="19849" status="PASS">
          <reporter-output>
          </reporter-output>
        </test-method> <!-- openBrowser -->
        <test-method is-config="true" signature="closeBrowser()[pri:0, instance:Tests.UseInsider@44e3a2b2]" started-at="2022-06-28T11:34:41Z" name="closeBrowser" finished-at="2022-06-28T11:34:45Z" duration-ms="4133" status="PASS">
          <reporter-output>
          </reporter-output>
        </test-method> <!-- closeBrowser -->
      </class> <!-- Tests.UseInsider -->
      <class name="Tests.TestClassUsingListeners">
        <test-method signature="failTestCase()[pri:0, instance:Tests.TestClassUsingListeners@101639ae]" started-at="2022-06-28T11:34:24Z" name="failTestCase" finished-at="2022-06-28T11:34:24Z" duration-ms="2" status="FAIL">
          <exception class="java.lang.AssertionError">
            <message>
              <![CDATA[null]]>
            </message>
            <full-stacktrace>
              <![CDATA[java.lang.AssertionError: null
at org.testng.Assert.fail(Assert.java:96)
at org.testng.Assert.fail(Assert.java:103)
at Tests.TestClassUsingListeners.failTestCase(TestClassUsingListeners.java:36)
at java.base/jdk.internal.reflect.DirectMethodHandleAccessor.invoke(DirectMethodHandleAccessor.java:104)
at java.base/java.lang.reflect.Method.invoke(Method.java:577)
at org.testng.internal.MethodInvocationHelper.invokeMethod(MethodInvocationHelper.java:124)
at org.testng.internal.Invoker.invokeMethod(Invoker.java:583)
at org.testng.internal.Invoker.invokeTestMethod(Invoker.java:719)
at org.testng.internal.Invoker.invokeTestMethods(Invoker.java:989)
at org.testng.internal.TestMethodWorker.invokeTestMethods(TestMethodWorker.java:125)
at org.testng.internal.TestMethodWorker.run(TestMethodWorker.java:109)
at org.testng.TestRunner.privateRun(TestRunner.java:648)
at org.testng.TestRunner.run(TestRunner.java:505)
at org.testng.SuiteRunner.runTest(SuiteRunner.java:455)
at org.testng.SuiteRunner.runSequentially(SuiteRunner.java:450)
at org.testng.SuiteRunner.privateRun(SuiteRunner.java:415)
at org.testng.SuiteRunner.run(SuiteRunner.java:364)
at org.testng.SuiteRunnerWorker.runSuite(SuiteRunnerWorker.java:52)
at org.testng.SuiteRunnerWorker.run(SuiteRunnerWorker.java:84)
at org.testng.TestNG.runSuitesSequentially(TestNG.java:1208)
at org.testng.TestNG.runSuitesLocally(TestNG.java:1137)
at org.testng.TestNG.runSuites(TestNG.java:1049)
at org.testng.TestNG.run(TestNG.java:1017)
at org.testng.remote.AbstractRemoteTestNG.run(AbstractRemoteTestNG.java:115)
at org.testng.remote.RemoteTestNG.initAndRun(RemoteTestNG.java:251)
at org.testng.remote.RemoteTestNG.main(RemoteTestNG.java:77)
]]>
            </full-stacktrace>
          </exception> <!-- java.lang.AssertionError -->
          <reporter-output>
          </reporter-output>
        </test-method> <!-- failTestCase -->
        <test-method signature="passTestCase()[pri:0, instance:Tests.TestClassUsingListeners@101639ae]" started-at="2022-06-28T11:34:24Z" name="passTestCase" finished-at="2022-06-28T11:34:41Z" duration-ms="16893" status="PASS">
          <reporter-output>
          </reporter-output>
        </test-method> <!-- passTestCase -->
        <test-method signature="skipTestCase()[pri:0, instance:Tests.TestClassUsingListeners@101639ae]" started-at="2022-06-28T11:34:41Z" name="skipTestCase" finished-at="2022-06-28T11:34:41Z" duration-ms="1" status="SKIP">
          <exception class="org.testng.SkipException">
            <message>
              <![CDATA[skipped]]>
            </message>
            <full-stacktrace>
              <![CDATA[org.testng.SkipException: skipped
at Tests.TestClassUsingListeners.skipTestCase(TestClassUsingListeners.java:43)
at java.base/jdk.internal.reflect.DirectMethodHandleAccessor.invoke(DirectMethodHandleAccessor.java:104)
at java.base/java.lang.reflect.Method.invoke(Method.java:577)
at org.testng.internal.MethodInvocationHelper.invokeMethod(MethodInvocationHelper.java:124)
at org.testng.internal.Invoker.invokeMethod(Invoker.java:583)
at org.testng.internal.Invoker.invokeTestMethod(Invoker.java:719)
at org.testng.internal.Invoker.invokeTestMethods(Invoker.java:989)
at org.testng.internal.TestMethodWorker.invokeTestMethods(TestMethodWorker.java:125)
at org.testng.internal.TestMethodWorker.run(TestMethodWorker.java:109)
at org.testng.TestRunner.privateRun(TestRunner.java:648)
at org.testng.TestRunner.run(TestRunner.java:505)
at org.testng.SuiteRunner.runTest(SuiteRunner.java:455)
at org.testng.SuiteRunner.runSequentially(SuiteRunner.java:450)
at org.testng.SuiteRunner.privateRun(SuiteRunner.java:415)
at org.testng.SuiteRunner.run(SuiteRunner.java:364)
at org.testng.SuiteRunnerWorker.runSuite(SuiteRunnerWorker.java:52)
at org.testng.SuiteRunnerWorker.run(SuiteRunnerWorker.java:84)
at org.testng.TestNG.runSuitesSequentially(TestNG.java:1208)
at org.testng.TestNG.runSuitesLocally(TestNG.java:1137)
at org.testng.TestNG.runSuites(TestNG.java:1049)
at org.testng.TestNG.run(TestNG.java:1017)
at org.testng.remote.AbstractRemoteTestNG.run(AbstractRemoteTestNG.java:115)
at org.testng.remote.RemoteTestNG.initAndRun(RemoteTestNG.java:251)
at org.testng.remote.RemoteTestNG.main(RemoteTestNG.java:77)
]]>
            </full-stacktrace>
          </exception> <!-- org.testng.SkipException -->
          <reporter-output>
          </reporter-output>
        </test-method> <!-- skipTestCase -->
      </class> <!-- Tests.TestClassUsingListeners -->
    </test> <!-- Test -->
  </suite> <!-- Suite -->
</testng-results>
